Workbook

Sheet LEEME
A1: Puente Charanal – Control 5D (BIM 4D/5D)
A2: Datos de ejemplo generados a partir del modelo charanal.frag (IFC2X3 / Revit 2026). Los valores de avance son ALEATORIOS.
A4: Hojas
A5: Parametros | B5: Datos generales, fecha de corte y umbral de atraso.
A6: Cronograma_5D | B6: Programación (inicio/fin), metrados extraídos del modelo BIM y presupuesto por tarea (WBS). Celdas amarillas = entrada.
A7: Avance_Mensual | B7: % de avance físico acumulado REAL por tarea al cierre de cada mes (5 meses de ejemplo: ene–may 2026). Completar el mes siguiente y mover la fecha de corte en Parametros.
A8: Curva_S | B8: Curva S acumulada programada (5D) vs ejecutada, con fórmulas y gráfico.
A9: Elementos_BIM | B9: Lista de elementos del modelo (sin armadura ni acopladores) con su tarea asignada. La armadura (22 333 barras) y los acopladores se asignan por Partida/Ubicación.
A11: Cómo se usa en el visor
A12: 1 | B12: El visor lee este Excel (Cronograma_5D, Avance_Mensual, Parametros) y pinta el modelo 3D según el estado de cada tarea en la fecha del deslizador 4D.
A13: 2 | B13: Puede reemplazar el Excel por el suyo con el botón "Cargar Excel" del visor, sin reiniciar nada.
A14: 3 | B14: El ID de cada tarea (columna A de Cronograma_5D) debe coincidir con el de public/data/element_map.json (se regenera con "npm run map").
A16: Colores | B16: Pendiente = gris · En proceso = azul · Terminado = verde · Atrasado = rojo (programado − real > umbral).
A17: Nota | B17: Se ocultan en el visor 2 losas auxiliares "Avance Eliminar" y 2 huecos (IfcOpeningElement) del modelo original.

Sheet Parametros
A1: Parámetros generales
A4: Proyecto | B4: Puente Peña 5D
A5: Subtítulo | B5: Control de Avance Técnico & Financiero
A6: Modalidad | B6: Licitación Directa Obra
A7: Moneda | B7: S/.
A8: Fecha inicio | B8: 46023
A9: Fecha fin | B9: 46326
A10: Fecha de corte | B10: 46173
A11: Umbral atraso (pts %) | B11: 0.1
A12: Presupuesto total | B12: =SUM(Cronograma_5D!M5:M31)

Sheet Cronograma_5D
A1: Cronograma 5D – programación, metrados BIM y presupuesto
A2: Amarillo = dato de entrada · Azul claro = fórmula. Metrados obtenidos del modelo charanal.frag.
A4: ID | B4: WBS | C4: Tarea | D4: Ubicación | E4: Elementos BIM | F4: Concreto (m³) | G4: Acero (kg) | H4: Otros (und) | I4: P.U. concreto (S/m³) | J4: P.U. acero (S/kg) | K4: P.U. otros (S/und) | L4: Costo fijo (S/) | M4: Presupuesto (S/) | N4: Inicio prog. | O4: Fin prog. | P4: Duración (d) | Q4: Predecesora | R4: % Prog. al corte | S4: % Real al corte | T4: Valor programado (S/) | U4: Valor ganado (S/) | V4: SPI | W4: Estado
A5: PIL-MD | B5: 1.1.1 | C5: Pilotes de cimentación | D5: Margen Derecha | E5: 6756 | F5: 1343.03 | G5: 292741 | H5: 2156 | I5: 1050 | J5: 5.8 | K5: 110 | L5: 0 | M5: =F5*I5+G5*J5+H5*K5+L5 | N5: 46027 | O5: 46081 | P5: =O5-N5+1 | R5: =MAX(0,MIN(1,(Parametros!$B$10-N5+1)/P5)) | S5: =IFERROR(INDEX(Avance_Mensual!$C5:$L5,1,MATCH(Parametros!$B$10,Avance_Mensual!$C$4:$L$4,0)),0) | T5: =M5*R5 | U5: =M5*S5 | V5: =IF(T5=0,"",U5/T5) | W5: =IF(S5>=1,"Terminado",IF(R5-S5>Parametros!$B$11,"Atrasado",IF(S5>0,"En proceso","Pendiente")))
A6: PCB-MD | B6: 1.1.2 | C6: Prueba de carga bidireccional | D6: Margen Derecha | E6: 392 | F6: 67.15 | G6: 14585 | H6: 108 | I6: 1050 | J6: 5.8 | K6: 110 | L6: 145000 | M6: =F6*I6+G6*J6+H6*K6+L6 | N6: 46027 | O6: 46053 | P6: =O6-N6+1 | R6: =MAX(0,MIN(1,(Parametros!$B$10-N6+1)/P6)) | S6: =IFERROR(INDEX(Avance_Mensual!$C6:$L6,1,MATCH(Parametros!$B$10,Avance_Mensual!$C$4:$L$4,0)),0) | T6: =M6*R6 | U6: =M6*S6 | V6: =IF(T6=0,"",U6/T6) | W6: =IF(S6>=1,"Terminado",IF(R6-S6>Parametros!$B$11,"Atrasado",IF(S6>0,"En proceso","Pendiente")))
A7: SOL-MD | B7: 1.1.3 | C7: Solado | D7: Margen Derecha | E7: 1 | F7: 18.04 | G7: 0 | H7: 0 | I7: 340 | J7: 0 | K7: 0 | L7: 0 | M7: =F7*I7+G7*J7+H7*K7+L7 | N7: 46083 | O7: 46091 | P7: =O7-N7+1 | Q7: PIL-MD | R7: =MAX(0,MIN(1,(Parametros!$B$10-N7+1)/P7)) | S7: =IFERROR(INDEX(Avance_Mensual!$C7:$L7,1,MATCH(Parametros!$B$10,Avance_Mensual!$C$4:$L$4,0)),0) | T7: =M7*R7 | U7: =M7*S7 | V7: =IF(T7=0,"",U7/T7) | W7: =IF(S7>=1,"Terminado",IF(R7-S7>Parametros!$B$11,"Atrasado",IF(S7>0,"En proceso","Pendiente")))
A8: CAB-MD | B8: 1.1.4 | C8: Cabezal | D8: Margen Derecha | E8: 3792 | F8: 714 | G8: 34163 | H8: 0 | I8: 690 | J8: 5.8 | K8: 0 | L8: 0 | M8: =F8*I8+G8*J8+H8*K8+L8 | N8: 46091 | O8: 46122 | P8: =O8-N8+1 | Q8: SOL-MD | R8: =MAX(0,MIN(1,(Parametros!$B$10-N8+1)/P8)) | S8: =IFERROR(INDEX(Avance_Mensual!$C8:$L8,1,MATCH(Parametros!$B$10,Avance_Mensual!$C$4:$L$4,0)),0) | T8: =M8*R8 | U8: =M8*S8 | V8: =IF(T8=0,"",U8/T8) | W8: =IF(S8>=1,"Terminado",IF(R8-S8>Parametros!$B$11,"Atrasado",IF(S8>0,"En proceso","Pendiente")))
A9: COL-MD | B9: 1.1.5 | C9: Columna y tirante | D9: Margen Derecha | E9: 2468 | F9: 75.54 | G9: 8192 | H9: 0 | I9: 980 | J9: 5.8 | K9: 0 | L9: 0 | M9: =F9*I9+G9*J9+H9*K9+L9 | N9: 46123 | O9: 46152 | P9: =O9-N9+1 | Q9: CAB-MD | R9: =MAX(0,MIN(1,(Parametros!$B$10-N9+1)/P9)) | S9: =IFERROR(INDEX(Avance_Mensual!$C9:$L9,1,MATCH(Parametros!$B$10,Avance_Mensual!$C$4:$L$4,0)),0) | T9: =M9*R9 | U9: =M9*S9 | V9: =IF(T9=0,"",U9/T9) | W9: =IF(S9>=1,"Terminado",IF(R9-S9>Parametros!$B$11,"Atrasado",IF(S9>0,"En proceso","Pendiente")))
A10: MUR-MD | B10: 1.1.6 | C10: Muros del estribo | D10: Margen Derecha | E10: 232 | F10: 427.38 | G10: 69981 | H10: 0 | I10: 690 | J10: 5.8 | K10: 0 | L10: 0 | M10: =F10*I10+G10*J10+H10*K10+L10 | N10: 46147 | O10: 46188 | P10: =O10-N10+1 | Q10: COL-MD | R10: =MAX(0,MIN(1,(Parametros!$B$10-N10+1)/P10)) | S10: =IFERROR(INDEX(Avance_Mensual!$C10:$L10,1,MATCH(Parametros!$B$10,Avance_Mensual!$C$4:$L$4,0)),0) | T10: =M10*R10 | U10: =M10*S10 | V10: =IF(T10=0,"",U10/T10) | W10: =IF(S10>=1,"Terminado",IF(R10-S10>Parametros!$B$11,"Atrasado",IF(S10>0,"En proceso","Pendiente")))
A11: BLQ-MD | B11: 1.1.7 | C11: Bloque y ménsula | D11: Margen Derecha | E11: 2 | F11: 12.95 | G11: 0 | H11: 0 | I11: 340 | J11: 0 | K11: 0 | L11: 0 | M11: =F11*I11+G11*J11+H11*K11+L11 | N11: 46183 | O11: 46203 | P11: =O11-N11+1 | Q11: MUR-MD | R11: =MAX(0,MIN(1,(Parametros!$B$10-N11+1)/P11)) | S11: =IFERROR(INDEX(Avance_Mensual!$C11:$L11,1,MATCH(Parametros!$B$10,Avance_Mensual!$C$4:$L$4,0)),0) | T11: =M11*R11 | U11: =M11*S11 | V11: =IF(T11=0,"",U11/T11) | W11: =IF(S11>=1,"Terminado",IF(R11-S11>Parametros!$B$11,"Atrasado",IF(S11>0,"En proceso","Pendiente")))
A12: POS-MD | B12: 1.1.8 | C12: Postensado (ductos) | D12: Margen Derecha | E12: 112 | F12: 0 | G12: 414 | H12: 24 | I12: 0 | J12: 5.8 | K12: 950 | L12: 0 | M12: =F12*I12+G12*J12+H12*K12+L12 | N12: 46174 | O12: 46203 | P12: =O12-N12+1 | Q12: MUR-MD | R12: =MAX(0,MIN(1,(Parametros!$B$10-N12+1)/P12)) | S12: =IFERROR(INDEX(Avance_Mensual!$C12:$L12,1,MATCH(Parametros!$B$10,Avance_Mensual!$C$4:$L$4,0)),0) | T12: =M12*R12 | U12: =M12*S12 | V12: =IF(T12=0,"",U12/T12) | W12: =IF(S12>=1,"Terminado",IF(R12-S12>Parametros!$B$11,"Atrasado",IF(S12>0,"En proceso","Pendiente")))
A13: DRE-MD | B13: 1.1.9 | C13: Drenaje PVC Ø4" | D13: Margen Derecha | E13: 32 | F13: 0 | G13: 0 | H13: 32 | I13: 0 | J13: 0 | K13: 145 | L13: 0 | M13: =F13*I13+G13*J13+H13*K13+L13 | N13: 46188 | O13: 46213 | P13: =O13-N13+1 | Q13: MUR-MD | R13: =MAX(0,MIN(1,(Parametros!$B$10-N13+1)/P13)) | S13: =IFERROR(INDEX(Avance_Mensual!$C13:$L13,1,MATCH(Parametros!$B$10,Avance_Mensual!$C$4:$L$4,0)),0) | T13: =M13*R13 | U13: =M13*S13 | V13: =IF(T13=0,"",U13/T13) | W13: =IF(S13>=1,"Terminado",IF(R13-S13>Parametros!$B$11,"Atrasado",IF(S13>0,"En proceso","Pendiente")))
A14: PIL-MI | B14: 1.2.1 | C14: Pilotes de cimentación | D14: Margen Izquierda | E14: 5160 | F14: 1060.29 | G14: 247959 | H14: 1440 | I14: 1050 | J14: 5.8 | K14: 110 | L14: 0 | M14: =F14*I14+G14*J14+H14*K14+L14 | N14: 46041 | O14: 46096 | P14: =O14-N14+1 | R14: =MAX(0,MIN(1,(Parametros!$B$10-N14+1)/P14)) | S14: =IFERROR(INDEX(Avance_Mensual!$C14:$L14,1,MATCH(Parametros!$B$10,Avance_Mensual!$C$4:$L$4,0)),0) | T14: =M14*R14 | U14: =M14*S14 | V14: =IF(T14=0,"",U14/T14) | W14: =IF(S14>=1,"Terminado",IF(R14-S14>Parametros!$B$11,"Atrasado",IF(S14>0,"En proceso","Pendiente")))
A15: PCB-MI | B15: 1.2.2 | C15: Prueba de carga bidireccional | D15: Margen Izquierda | E15: 268 | F15: 53.01 | G15: 12348 | H15: 36 | I15: 1050 | J15: 5.8 | K15: 110 | L15: 145000 | M15: =F15*I15+G15*J15+H15*K15+L15 | N15: 46034 | O15: 46059 | P15: =O15-N15+1 | R15: =MAX(0,MIN(1,(Parametros!$B$10-N15+1)/P15)) | S15: =IFERROR(INDEX(Avance_Mensual!$C15:$L15,1,MATCH(Parametros!$B$10,Avance_Mensual!$C$4:$L$4,0)),0) | T15: =M15*R15 | U15: =M15*S15 | V15: =IF(T15=0,"",U15/T15) | W15: =IF(S15>=1,"Terminado",IF(R15-S15>Parametros!$B$11,"Atrasado",IF(S15>0,"En proceso","Pendiente")))
A16: SOL-MI | B16: 1.2.3 | C16: Solado | D16: Margen Izquierda | E16: 1 | F16: 18.04 | G16: 0 | H16: 0 | I16: 340 | J16: 0 | K16: 0 | L16: 0 | M16: =F16*I16+G16*J16+H16*K16+L16 | N16: 46097 | O16: 46106 | P16: =O16-N16+1 | Q16: PIL-MI | R16: =MAX(0,MIN(1,(Parametros!$B$10-N16+1)/P16)) | S16: =IFERROR(INDEX(Avance_Mensual!$C16:$L16,1,MATCH(Parametros!$B$10,Avance_Mensual!$C$4:$L$4,0)),0) | T16: =M16*R16 | U16: =M16*S16 | V16: =IF(T16=0,"",U16/T16) | W16: =IF(S16>=1,"Terminado",IF(R16-S16>Parametros!$B$11,"Atrasado",IF(S16>0,"En proceso","Pendiente")))
A17: CAB-MI | B17: 1.2.4 | C17: Cabezal | D17: Margen Izquierda | E17: 3792 | F17: 714 | G17: 34163 | H17: 0 | I17: 690 | J17: 5.8 | K17: 0 | L17: 0 | M17: =F17*I17+G17*J17+H17*K17+L17 | N17: 46107 | O17: 46137 | P17: =O17-N17+1 | Q17: SOL-MI | R17: =MAX(0,MIN(1,(Parametros!$B$10-N17+1)/P17)) | S17: =IFERROR(INDEX(Avance_Mensual!$C17:$L17,1,MATCH(Parametros!$B$10,Avance_Mensual!$C$4:$L$4,0)),0) | T17: =M17*R17 | U17: =M17*S17 | V17: =IF(T17=0,"",U17/T17) | W17: =IF(S17>=1,"Terminado",IF(R17-S17>Parametros!$B$11,"Atrasado",IF(S17>0,"En proceso","Pendiente")))
A18: COL-MI | B18: 1.2.5 | C18: Columna y tirante | D18: Margen Izquierda | E18: 2468 | F18: 75.54 | G18: 8192 | H18: 0 | I18: 980 | J18: 5.8 | K18: 0 | L18: 0 | M18: =F18*I18+G18*J18+H18*K18+L18 | N18: 46138 | O18: 46167 | P18: =O18-N18+1 | Q18: CAB-MI | R18: =MAX(0,MIN(1,(Parametros!$B$10-N18+1)/P18)) | S18: =IFERROR(INDEX(Avance_Mensual!$C18:$L18,1,MATCH(Parametros!$B$10,Avance_Mensual!$C$4:$L$4,0)),0) | T18: =M18*R18 | U18: =M18*S18 | V18: =IF(T18=0,"",U18/T18) | W18: =IF(S18>=1,"Terminado",IF(R18-S18>Parametros!$B$11,"Atrasado",IF(S18>0,"En proceso","Pendiente")))
A19: MUR-MI | B19: 1.2.6 | C19: Muros del estribo | D19: Margen Izquierda | E19: 232 | F19: 427.38 | G19: 69981 | H19: 0 | I19: 690 | J19: 5.8 | K19: 0 | L19: 0 | M19: =F19*I19+G19*J19+H19*K19+L19 | N19: 46162 | O19: 46203 | P19: =O19-N19+1 | Q19: COL-MI | R19: =MAX(0,MIN(1,(Parametros!$B$10-N19+1)/P19)) | S19: =IFERROR(INDEX(Avance_Mensual!$C19:$L19,1,MATCH(Parametros!$B$10,Avance_Mensual!$C$4:$L$4,0)),0) | T19: =M19*R19 | U19: =M19*S19 | V19: =IF(T19=0,"",U19/T19) | W19: =IF(S19>=1,"Terminado",IF(R19-S19>Parametros!$B$11,"Atrasado",IF(S19>0,"En proceso","Pendiente")))
A20: BLQ-MI | B20: 1.2.7 | C20: Bloque y ménsula | D20: Margen Izquierda | E20: 2 | F20: 12.95 | G20: 0 | H20: 0 | I20: 340 | J20: 0 | K20: 0 | L20: 0 | M20: =F20*I20+G20*J20+H20*K20+L20 | N20: 46198 | O20: 46218 | P20: =O20-N20+1 | Q20: MUR-MI | R20: =MAX(0,MIN(1,(Parametros!$B$10-N20+1)/P20)) | S20: =IFERROR(INDEX(Avance_Mensual!$C20:$L20,1,MATCH(Parametros!$B$10,Avance_Mensual!$C$4:$L$4,0)),0) | T20: =M20*R20 | U20: =M20*S20 | V20: =IF(T20=0,"",U20/T20) | W20: =IF(S20>=1,"Terminado",IF(R20-S20>Parametros!$B$11,"Atrasado",IF(S20>0,"En proceso","Pendiente")))
A21: POS-MI | B21: 1.2.8 | C21: Postensado (ductos) | D21: Margen Izquierda | E21: 112 | F21: 0 | G21: 414 | H21: 24 | I21: 0 | J21: 5.8 | K21: 950 | L21: 0 | M21: =F21*I21+G21*J21+H21*K21+L21 | N21: 46188 | O21: 46213 | P21: =O21-N21+1 | Q21: MUR-MI | R21: =MAX(0,MIN(1,(Parametros!$B$10-N21+1)/P21)) | S21: =IFERROR(INDEX(Avance_Mensual!$C21:$L21,1,MATCH(Parametros!$B$10,Avance_Mensual!$C$4:$L$4,0)),0) | T21: =M21*R21 | U21: =M21*S21 | V21: =IF(T21=0,"",U21/T21) | W21: =IF(S21>=1,"Terminado",IF(R21-S21>Parametros!$B$11,"Atrasado",IF(S21>0,"En proceso","Pendiente")))
A22: TAB-MD-D1 | B22: 2.1.1 | C22: Dovela D1 (diafragma extremo) | D22: Margen Derecha | E22: 8 | F22: 112.95 | G22: 75 | H22: 0 | I22: 1250 | J22: 5.8 | K22: 0 | L22: 0 | M22: =F22*I22+G22*J22+H22*K22+L22 | N22: 46204 | O22: 46218 | P22: =O22-N22+1 | Q22: BLQ-MD | R22: =MAX(0,MIN(1,(Parametros!$B$10-N22+1)/P22)) | S22: =IFERROR(INDEX(Avance_Mensual!$C22:$L22,1,MATCH(Parametros!$B$10,Avance_Mensual!$C$4:$L$4,0)),0) | T22: =M22*R22 | U22: =M22*S22 | V22: =IF(T22=0,"",U22/T22) | W22: =IF(S22>=1,"Terminado",IF(R22-S22>Parametros!$B$11,"Atrasado",IF(S22>0,"En proceso","Pendiente")))
A23: TAB-MD-D2 | B23: 2.1.2 | C23: Dovela D2 (sobre estribo) | D23: Margen Derecha | E23: 5 | F23: 140.49 | G23: 70 | H23: 0 | I23: 1250 | J23: 5.8 | K23: 0 | L23: 0 | M23: =F23*I23+G23*J23+H23*K23+L23 | N23: 46216 | O23: 46234 | P23: =O23-N23+1 | Q23: TAB-MD-D1 | R23: =MAX(0,MIN(1,(Parametros!$B$10-N23+1)/P23)) | S23: =IFERROR(INDEX(Avance_Mensual!$C23:$L23,1,MATCH(Parametros!$B$10,Avance_Mensual!$C$4:$L$4,0)),0) | T23: =M23*R23 | U23: =M23*S23 | V23: =IF(T23=0,"",U23/T23) | W23: =IF(S23>=1,"Terminado",IF(R23-S23>Parametros!$B$11,"Atrasado",IF(S23>0,"En proceso","Pendiente")))
A24: TAB-MD-D3 | B24: 2.1.3 | C24: Dovela D3 (sobre estribo) | D24: Margen Derecha | E24: 17 | F24: 112.69 | G24: 9419 | H24: 0 | I24: 1250 | J24: 5.8 | K24: 0 | L24: 0 | M24: =F24*I24+G24*J24+H24*K24+L24 | N24: 46232 | O24: 46251 | P24: =O24-N24+1 | Q24: TAB-MD-D2 | R24: =MAX(0,MIN(1,(Parametros!$B$10-N24+1)/P24)) | S24: =IFERROR(INDEX(Avance_Mensual!$C24:$L24,1,MATCH(Parametros!$B$10,Avance_Mensual!$C$4:$L$4,0)),0) | T24: =M24*R24 | U24: =M24*S24 | V24: =IF(T24=0,"",U24/T24) | W24: =IF(S24>=1,"Terminado",IF(R24-S24>Parametros!$B$11,"Atrasado",IF(S24>0,"En proceso","Pendiente")))
A25: TAB-MD-D4 | B25: 2.1.4 | C25: Dovela D4 (luz central) | D25: Margen Derecha | E25: 318 | F25: 243.75 | G25: 216249 | H25: 0 | I25: 1250 | J25: 5.8 | K25: 0 | L25: 0 | M25: =F25*I25+G25*J25+H25*K25+L25 | N25: 46248 | O25: 46277 | P25: =O25-N25+1 | Q25: TAB-MD-D3 | R25: =MAX(0,MIN(1,(Parametros!$B$10-N25+1)/P25)) | S25: =IFERROR(INDEX(Avance_Mensual!$C25:$L25,1,MATCH(Parametros!$B$10,Avance_Mensual!$C$4:$L$4,0)),0) | T25: =M25*R25 | U25: =M25*S25 | V25: =IF(T25=0,"",U25/T25) | W25: =IF(S25>=1,"Terminado",IF(R25-S25>Parametros!$B$11,"Atrasado",IF(S25>0,"En proceso","Pendiente")))
A26: TAB-MD-D5 | B26: 2.1.5 | C26: Dovela D5 (luz central) | D26: Margen Derecha | E26: 241 | F26: 207.45 | G26: 117319 | H26: 0 | I26: 1250 | J26: 5.8 | K26: 0 | L26: 0 | M26: =F26*I26+G26*J26+H26*K26+L26 | N26: 46273 | O26: 46301 | P26: =O26-N26+1 | Q26: TAB-MD-D4 | R26: =MAX(0,MIN(1,(Parametros!$B$10-N26+1)/P26)) | S26: =IFERROR(INDEX(Avance_Mensual!$C26:$L26,1,MATCH(Parametros!$B$10,Avance_Mensual!$C$4:$L$4,0)),0) | T26: =M26*R26 | U26: =M26*S26 | V26: =IF(T26=0,"",U26/T26) | W26: =IF(S26>=1,"Terminado",IF(R26-S26>Parametros!$B$11,"Atrasado",IF(S26>0,"En proceso","Pendiente")))
A27: TAB-MI-D1 | B27: 2.2.1 | C27: Dovela D1 (diafragma extremo) | D27: Margen Izquierda | E27: 2 | F27: 112.95 | G27: 25 | H27: 0 | I27: 1250 | J27: 5.8 | K27: 0 | L27: 0 | M27: =F27*I27+G27*J27+H27*K27+L27 | N27: 46219 | O27: 46233 | P27: =O27-N27+1 | Q27: BLQ-MI | R27: =MAX(0,MIN(1,(Parametros!$B$10-N27+1)/P27)) | S27: =IFERROR(INDEX(Avance_Mensual!$C27:$L27,1,MATCH(Parametros!$B$10,Avance_Mensual!$C$4:$L$4,0)),0) | T27: =M27*R27 | U27: =M27*S27 | V27: =IF(T27=0,"",U27/T27) | W27: =IF(S27>=1,"Terminado",IF(R27-S27>Parametros!$B$11,"Atrasado",IF(S27>0,"En proceso","Pendiente")))
... A31: TAB-MI-D5 | B31: 2.2.5 | C31: Dovela D5 (luz central) | D31: Margen Izquierda | E31: 7 | F31: 207.45 | G31: 1061 | H31: 0 | I31: 1250 | J31: 5.8 | K31: 0 | L31: 0 | M31: =F31*I31+G31*J31+H31*K31+L31 | N31: 46288 | O31: 46326 | P31: =O31-N31+1 | Q31: TAB-MI-D4 | R31: =MAX(0,MIN(1,(Parametros!$B$10-N31+1)/P31)) | S31: =IFERROR(INDEX(Avance_Mensual!$C31:$L31,1,MATCH(Parametros!$B$10,Avance_Mensual!$C$4:$L$4,0)),0) | T31: =M31*R31 | U31: =M31*S31 | V31: =IF(T31=0,"",U31/T31) | W31: =IF(S31>=1,"Terminado",IF(R31-S31>Parametros!$B$11,"Atrasado",IF(S31>0,"En proceso","Pendiente")))
C32: TOTAL | E32: =SUM(E5:E31) | F32: =SUM(F5:F31) | G32: =SUM(G5:G31) | H32: =SUM(H5:H31) | M32: =SUM(M5:M31) | R32: =T32/M32 | S32: =U32/M32 | T32: =SUM(T5:T31) | U32: =SUM(U5:U31) | V32: =U32/T32

Sheet Avance_Mensual
A1: % de avance físico REAL acumulado por tarea (cierre de mes)
A2: Datos aleatorios de ejemplo (5 meses). Deje en blanco los meses futuros.
A4: ID | B4: Tarea | C4: 46053 | D4: 46081 | E4: 46112 | F4: 46142 | G4: 46173 | H4: 46203 | I4: 46234 | J4: 46265 | K4: 46295 | L4: 46326
A5: =Cronograma_5D!A5 | B5: =Cronograma_5D!C5 | C5: 0.4 | D5: 0.95 | E5: 1 | F5: 1 | G5: 1
A6: =Cronograma_5D!A6 | B6: =Cronograma_5D!C6 | C6: 0.6 | D6: 1 | E6: 1 | F6: 1 | G6: 1
A7: =Cronograma_5D!A7 | B7: =Cronograma_5D!C7 | C7: 0 | D7: 0 | E7: 1 | F7: 1 | G7: 1
A8: =Cronograma_5D!A8 | B8: =Cronograma_5D!C8 | C8: 0 | D8: 0 | E8: 0.25 | F8: 1 | G8: 1
A9: =Cronograma_5D!A9 | B9: =Cronograma_5D!C9 | C9: 0 | D9: 0 | E9: 0 | F9: 0.1 | G9: 0.8
A10: =Cronograma_5D!A10 | B10: =Cronograma_5D!C10 | C10: 0 | D10: 0 | E10: 0 | F10: 0 | G10: 0.4
A11: =Cronograma_5D!A11 | B11: =Cronograma_5D!C11 | C11: 0 | D11: 0 | E11: 0 | F11: 0 | G11: 0
A12: =Cronograma_5D!A12 | B12: =Cronograma_5D!C12 | C12: 0 | D12: 0 | E12: 0 | F12: 0 | G12: 0
A13: =Cronograma_5D!A13 | B13: =Cronograma_5D!C13 | C13: 0 | D13: 0 | E13: 0 | F13: 0 | G13: 0
A14: =Cronograma_5D!A14 | B14: =Cronograma_5D!C14 | C14: 0.1 | D14: 0.7 | E14: 1 | F14: 1 | G14: 1
A15: =Cronograma_5D!A15 | B15: =Cronograma_5D!C15 | C15: 0.7 | D15: 1 | E15: 1 | F15: 1 | G15: 1
A16: =Cronograma_5D!A16 | B16: =Cronograma_5D!C16 | C16: 0 | D16: 0 | E16: 0.8 | F16: 1 | G16: 1
... A31: =Cronograma_5D!A31 | B31: =Cronograma_5D!C31 | C31: 0 | D31: 0 | E31: 0 | F31: 0 | G31: 0

Sheet Curva_S
A1: Curva S – valor programado (5D) vs valor ejecutado
A2: S/ acumulados al cierre de cada mes
A4: Mes | B4: Fecha corte | C4: Programado acum. (S/) | D4: Ejecutado acum. (S/) | E4: % Prog. acum. | F4: % Real acum. | G4: Programado mensual (S/) | H4: Ejecutado mensual (S/) | I4: SPI
A5: Ene-26 | B5: =Avance_Mensual!C4 | C5: =SUMPRODUCT(Cronograma_5D!$M$5:$M$31*((($B5>=Cronograma_5D!$N$5:$N$31)*($B5<=Cronograma_5D!$O$5:$O$31)*($B5-Cronograma_5D!$N$5:$N$31+1)/Cronograma_5D!$P$5:$P$31)+($B5>Cronograma_5D!$O$5:$O$31))) | D5: =IF(COUNT(Avance_Mensual!C$5:C$31)=0,NA(),SUMPRODUCT(Cronograma_5D!$M$5:$M$31,Avance_Mensual!C$5:C$31)) | E5: =C5/Cronograma_5D!$M$32 | F5: =IFERROR(D5/Cronograma_5D!$M$32,NA()) | G5: =C5 | H5: =IFERROR(D5,NA()) | I5: =IFERROR(D5/C5,NA())
A6: Feb-26 | B6: =Avance_Mensual!D4 | C6: =SUMPRODUCT(Cronograma_5D!$M$5:$M$31*((($B6>=Cronograma_5D!$N$5:$N$31)*($B6<=Cronograma_5D!$O$5:$O$31)*($B6-Cronograma_5D!$N$5:$N$31+1)/Cronograma_5D!$P$5:$P$31)+($B6>Cronograma_5D!$O$5:$O$31))) | D6: =IF(COUNT(Avance_Mensual!D$5:D$31)=0,NA(),SUMPRODUCT(Cronograma_5D!$M$5:$M$31,Avance_Mensual!D$5:D$31)) | E6: =C6/Cronograma_5D!$M$32 | F6: =IFERROR(D6/Cronograma_5D!$M$32,NA()) | G6: =C6-C5 | H6: =IFERROR(D6-D5,NA()) | I6: =IFERROR(D6/C6,NA())
A7: Mar-26 | B7: =Avance_Mensual!E4 | C7: =SUMPRODUCT(Cronograma_5D!$M$5:$M$31*((($B7>=Cronograma_5D!$N$5:$N$31)*($B7<=Cronograma_5D!$O$5:$O$31)*($B7-Cronograma_5D!$N$5:$N$31+1)/Cronograma_5D!$P$5:$P$31)+($B7>Cronograma_5D!$O$5:$O$31))) | D7: =IF(COUNT(Avance_Mensual!E$5:E$31)=0,NA(),SUMPRODUCT(Cronograma_5D!$M$5:$M$31,Avance_Mensual!E$5:E$31)) | E7: =C7/Cronograma_5D!$M$32 | F7: =IFERROR(D7/Cronograma_5D!$M$32,NA()) | G7: =C7-C6 | H7: =IFERROR(D7-D6,NA()) | I7: =IFERROR(D7/C7,NA())
A8: Abr-26 | B8: =Avance_Mensual!F4 | C8: =SUMPRODUCT(Cronograma_5D!$M$5:$M$31*((($B8>=Cronograma_5D!$N$5:$N$31)*($B8<=Cronograma_5D!$O$5:$O$31)*($B8-Cronograma_5D!$N$5:$N$31+1)/Cronograma_5D!$P$5:$P$31)+($B8>Cronograma_5D!$O$5:$O$31))) | D8: =IF(COUNT(Avance_Mensual!F$5:F$31)=0,NA(),SUMPRODUCT(Cronograma_5D!$M$5:$M$31,Avance_Mensual!F$5:F$31)) | E8: =C8/Cronograma_5D!$M$32 | F8: =IFERROR(D8/Cronograma_5D!$M$32,NA()) | G8: =C8-C7 | H8: =IFERROR(D8-D7,NA()) | I8: =IFERROR(D8/C8,NA())
A9: May-26 | B9: =Avance_Mensual!G4 | C9: =SUMPRODUCT(Cronograma_5D!$M$5:$M$31*((($B9>=Cronograma_5D!$N$5:$N$31)*($B9<=Cronograma_5D!$O$5:$O$31)*($B9-Cronograma_5D!$N$5:$N$31+1)/Cronograma_5D!$P$5:$P$31)+($B9>Cronograma_5D!$O$5:$O$31))) | D9: =IF(COUNT(Avance_Mensual!G$5:G$31)=0,NA(),SUMPRODUCT(Cronograma_5D!$M$5:$M$31,Avance_Mensual!G$5:G$31)) | E9: =C9/Cronograma_5D!$M$32 | F9: =IFERROR(D9/Cronograma_5D!$M$32,NA()) | G9: =C9-C8 | H9: =IFERROR(D9-D8,NA()) | I9: =IFERROR(D9/C9,NA())
A10: Jun-26 | B10: =Avance_Mensual!H4 | C10: =SUMPRODUCT(Cronograma_5D!$M$5:$M$31*((($B10>=Cronograma_5D!$N$5:$N$31)*($B10<=Cronograma_5D!$O$5:$O$31)*($B10-Cronograma_5D!$N$5:$N$31+1)/Cronograma_5D!$P$5:$P$31)+($B10>Cronograma_5D!$O$5:$O$31))) | D10: =IF(COUNT(Avance_Mensual!H$5:H$31)=0,NA(),SUMPRODUCT(Cronograma_5D!$M$5:$M$31,Avance_Mensual!H$5:H$31)) | E10: =C10/Cronograma_5D!$M$32 | F10: =IFERROR(D10/Cronograma_5D!$M$32,NA()) | G10: =C10-C9 | H10: =IFERROR(D10-D9,NA()) | I10: =IFERROR(D10/C10,NA())
A11: Jul-26 | B11: =Avance_Mensual!I4 | C11: =SUMPRODUCT(Cronograma_5D!$M$5:$M$31*((($B11>=Cronograma_5D!$N$5:$N$31)*($B11<=Cronograma_5D!$O$5:$O$31)*($B11-Cronograma_5D!$N$5:$N$31+1)/Cronograma_5D!$P$5:$P$31)+($B11>Cronograma_5D!$O$5:$O$31))) | D11: =IF(COUNT(Avance_Mensual!I$5:I$31)=0,NA(),SUMPRODUCT(Cronograma_5D!$M$5:$M$31,Avance_Mensual!I$5:I$31)) | E11: =C11/Cronograma_5D!$M$32 | F11: =IFERROR(D11/Cronograma_5D!$M$32,NA()) | G11: =C11-C10 | H11: =IFERROR(D11-D10,NA()) | I11: =IFERROR(D11/C11,NA())
A12: Ago-26 | B12: =Avance_Mensual!J4 | C12: =SUMPRODUCT(Cronograma_5D!$M$5:$M$31*((($B12>=Cronograma_5D!$N$5:$N$31)*($B12<=Cronograma_5D!$O$5:$O$31)*($B12-Cronograma_5D!$N$5:$N$31+1)/Cronograma_5D!$P$5:$P$31)+($B12>Cronograma_5D!$O$5:$O$31))) | D12: =IF(COUNT(Avance_Mensual!J$5:J$31)=0,NA(),SUMPRODUCT(Cronograma_5D!$M$5:$M$31,Avance_Mensual!J$5:J$31)) | E12: =C12/Cronograma_5D!$M$32 | F12: =IFERROR(D12/Cronograma_5D!$M$32,NA()) | G12: =C12-C11 | H12: =IFERROR(D12-D11,NA()) | I12: =IFERROR(D12/C12,NA())
A13: Sep-26 | B13: =Avance_Mensual!K4 | C13: =SUMPRODUCT(Cronograma_5D!$M$5:$M$31*((($B13>=Cronograma_5D!$N$5:$N$31)*($B13<=Cronograma_5D!$O$5:$O$31)*($B13-Cronograma_5D!$N$5:$N$31+1)/Cronograma_5D!$P$5:$P$31)+($B13>Cronograma_5D!$O$5:$O$31))) | D13: =IF(COUNT(Avance_Mensual!K$5:K$31)=0,NA(),SUMPRODUCT(Cronograma_5D!$M$5:$M$31,Avance_Mensual!K$5:K$31)) | E13: =C13/Cronograma_5D!$M$32 | F13: =IFERROR(D13/Cronograma_5D!$M$32,NA()) | G13: =C13-C12 | H13: =IFERROR(D13-D12,NA()) | I13: =IFERROR(D13/C13,NA())
A14: Oct-26 | B14: =Avance_Mensual!L4 | C14: =SUMPRODUCT(Cronograma_5D!$M$5:$M$31*((($B14>=Cronograma_5D!$N$5:$N$31)*($B14<=Cronograma_5D!$O$5:$O$31)*($B14-Cronograma_5D!$N$5:$N$31+1)/Cronograma_5D!$P$5:$P$31)+($B14>Cronograma_5D!$O$5:$O$31))) | D14: =IF(COUNT(Avance_Mensual!L$5:L$31)=0,NA(),SUMPRODUCT(Cronograma_5D!$M$5:$M$31,Avance_Mensual!L$5:L$31)) | E14: =C14/Cronograma_5D!$M$32 | F14: =IFERROR(D14/Cronograma_5D!$M$32,NA()) | G14: =C14-C13 | H14: =IFERROR(D14-D13,NA()) | I14: =IFERROR(D14/C14,NA())

Sheet Elementos_BIM
A1: Elementos del modelo BIM (sin armadura ni acopladores)
A2: localId = identificador dentro de charanal.frag · Tarea = ID de Cronograma_5D
A4: localId | B4: GUID | C4: Categoría IFC | D4: Nombre | E4: Código | F4: Partida | G4: Ubicación | H4: Elemento | I4: Tarea ID | J4: Volumen (m³) | K4: Estado AO (modelo)
A5: 966 | B5: 3qZUcMynj20Rs4CLv$8u3O | C5: SLAB | D5: Losa de cimentación:Drenaje_Bloque_500x500_fc100:419055 | E5: ED-B1 | F5: Estribos | G5: Margen Derecha | H5: Bloque | I5: BLQ-MD | J5: 11.9 | K5: No iniciado
A6: 1804400 | B6: 014613D2j3Qx1EYpOdi2Zs | C6: BEAM | D6: Cimentacion_Mensula:Estribos_Mensula_ConcretoC(f'c=280kg/cm2):800014 | E6: ED-M1 | F6: Estribos | G6: Margen Derecha | H6: Mensula | I6: BLQ-MD | J6: 1.05 | K6: No iniciado
A7: 2078750 | B7: 31IX94I6r2efzgAGrOkFTj | C7: SLAB | D7: Losa de cimentación:Drenaje_Bloque_500x500_fc100:1525818 | E7: ED-B1 | F7: Estribos | G7: Margen Izquierda | H7: Bloque | I7: BLQ-MI | J7: 11.9
A8: 2224454 | B8: 31IX94I6r2efzgAGrOkF2S | C8: BEAM | D8: Cimentacion_Mensula:Estribos_Mensula_ConcretoC(f'c=280kg/cm2):1527755 | E8: ED-M1 | F8: Estribos | G8: Margen Izquierda | H8: Mensula | I8: BLQ-MI | J8: 1.05 | K8: No iniciado
A9: 95 | B9: 1eNJRIYerEFfvMqFI4H3Ru | C9: SLAB | D9: Losa de cimentación:Estribos_Cabezal_e2000_fc280:398264 | E9: ED-CA1 | F9: Estribos | G9: Margen Derecha | H9: Cabezal | I9: CAB-MD | J9: 714 | K9: Ejecutado
A10: 1550156 | B10: 3Qoa7x4w5C5RyJcivX0FnP | C10: SLAB | D10: Losa de cimentación:Estribos_Cabezal_e2000_fc280:716317 | E10: EI-CA1 | F10: Estribos | G10: Margen Izquierda | H10: Cabezal | I10: CAB-MI | J10: 714 | K10: Ejecutado
A11: 798 | B11: 2t1$kOTDX16wjqwHtKTv40 | C11: SLAB | D11: Estribos_Columna:Estribo_Columna_L6294_A1200_fc420:414372 | E11: ED-CO1 | F11: Estribos | G11: Margen Derecha | H11: Columna | I11: COL-MD | J11: 55.135 | K11: No iniciado
A12: 860 | B12: 2hCL6D33vDBwna1xopuPSX | C12: SLAB | D12: Estribos_Tirante:Estribo_Tirante_L5000_A500_fc420:415783 | E12: ED-T1 | F12: Estribos | G12: Margen Derecha | H12: Tirante | I12: COL-MD | J12: 20.403 | K12: No iniciado
A13: 2078665 | B13: 31IX94I6r2efzgAGrOkFTW | C13: SLAB | D13: Estribos_Columna:Estribo_Columna_L6294_A1200_fc420:1525815 | E13: ED-CO1 | F13: Estribos | G13: Margen Izquierda | H13: Columna | I13: COL-MI | J13: 55.135
A14: 2078705 | B14: 31IX94I6r2efzgAGrOkFTl | C14: SLAB | D14: Estribos_Tirante:Estribo_Tirante_L5000_A500_fc420:1525816 | E14: ED-T1 | F14: Estribos | G14: Margen Izquierda | H14: Tirante | I14: COL-MI | J14: 20.403
A15: 1061 | B15: 0o80Peddn54RM98uOzdBOw | C15: FLOWSEGMENT | D15: Tipos de tubería:Tuberia PVC-SAP:419967 | F15: Estribos | G15: Margen Derecha | H15: TUBOPVCØ4" | I15: DRE-MD | K15: No iniciado
A16: 1164 | B16: 0o80Peddn54RM98uOzdBFp | C16: FLOWSEGMENT | D16: Tipos de tubería:Tuberia PVC-SAP:421302 | F16: Estribos | G16: Margen Derecha | H16: TUBOPVCØ4" | I16: DRE-MD | K16: No iniciado
A17: 1229 | B17: 0o80Peddn54RM98uOzdBEA | C17: FLOWSEGMENT | D17: Tipos de tubería:Tuberia PVC-SAP:421327 | F17: Estribos | G17: Margen Derecha | H17: TUBOPVCØ4" | I17: DRE-MD | K17: No iniciado
A18: 1294 | B18: 0o80Peddn54RM98uOzdBEl | C18: FLOWSEGMENT | D18: Tipos de tubería:Tuberia PVC-SAP:421354 | F18: Estribos | G18: Margen Derecha | H18: TUBOPVCØ4" | I18: DRE-MD | K18: No iniciado
A19: 2467637 | B19: 3c6cu7lgP8KvmnM44lUGSH | C19: FLOWSEGMENT | D19: Tipos de tubería:Tuberia PVC-SAP:1650887 | F19: Estribos | G19: Margen Derecha | H19: TUBOPVCØ4" | I19: DRE-MD | K19: No iniciado
A20: 2467702 | B20: 3c6cu7lgP8KvmnM44lUGR1 | C20: FLOWSEGMENT | D20: Tipos de tubería:Tuberia PVC-SAP:1650967 | F20: Estribos | G20: Margen Derecha | H20: TUBOPVCØ4" | I20: DRE-MD | K20: No iniciado
A21: 2467767 | B21: 3c6cu7lgP8KvmnM44lUGGE | C21: FLOWSEGMENT | D21: Tipos de tubería:Tuberia PVC-SAP:1651672 | F21: Estribos | G21: Margen Derecha | H21: TUBOPVCØ4" | I21: DRE-MD | K21: No iniciado
A22: 2467832 | B22: 3c6cu7lgP8KvmnM44lUGGn | C22: FLOWSEGMENT | D22: Tipos de tubería:Tuberia PVC-SAP:1651687 | F22: Estribos | G22: Margen Derecha | H22: TUBOPVCØ4" | I22: DRE-MD | K22: No iniciado
A23: 2467897 | B23: 3c6cu7lgP8KvmnM44lUGGY | C23: FLOWSEGMENT | D23: Tipos de tubería:Tuberia PVC-SAP:1651700 | F23: Estribos | G23: Margen Derecha | H23: TUBOPVCØ4" | I23: DRE-MD | K23: No iniciado
A24: 2467962 | B24: 3c6cu7lgP8KvmnM44lUGFN | C24: FLOWSEGMENT | D24: Tipos de tubería:Tuberia PVC-SAP:1651713 | F24: Estribos | G24: Margen Derecha | H24: TUBOPVCØ4" | I24: DRE-MD | K24: No iniciado
A25: 2468027 | B25: 3c6cu7lgP8KvmnM44lUGF4 | C25: FLOWSEGMENT | D25: Tipos de tubería:Tuberia PVC-SAP:1651730 | F25: Estribos | G25: Margen Derecha | H25: TUBOPVCØ4" | I25: DRE-MD | K25: No iniciado
A26: 2468092 | B26: 3c6cu7lgP8KvmnM44lUG_s | C26: FLOWSEGMENT | D26: Tipos de tubería:Tuberia PVC-SAP:1652832 | F26: Estribos | G26: Margen Derecha | H26: TUBOPVCØ4" | I26: DRE-MD | K26: No iniciado
... A46: 2469392 | B46: 0FZutSDmbA7u4L9MSLIIGl | C46: FLOWSEGMENT | D46: Tipos de tubería:Tuberia PVC-SAP:1654610 | F46: Estribos | G46: Margen Derecha | H46: TUBOPVCØ4" | I46: DRE-MD | K46: Ejecutado
A47: 389 | B47: 2t1$kOTDX16wjqwHtKTucI | C47: SLAB | D47: Estribos_MurosFrontales:Estribo_MFrontal_e1200_fc280:412214 | E47: ED-M2 | F47: Estribos | G47: Margen Derecha | H47: MuroFrontal | I47: MUR-MD | J47: 39.085 | K47: No iniciado
A48: 453 | B48: 2t1$kOTDX16wjqwHtKTu_n | C48: SLAB | D48: Estribos_MurosFrontales:Estribo_MFrontal_e1200_fc280:412693 | E48: ED-MF1 | F48: Estribos | G48: Margen Derecha | H48: MuroFrontal | I48: MUR-MD | J48: 39.085 | K48: No iniciado
A49: 543 | B49: 2t1$kOTDX16wjqwHtKTvF5 | C49: SLAB | D49: Estribos_MurosPosterior:Estribo_MPosterior_fc280:413793 | E49: ED-MP1 | F49: Estribos | G49: Margen Derecha | H49: MuroPosterior | I49: MUR-MD | J49: 163.632 | K49: No iniciado
A50: 650 | B50: 2t1$kOTDX16wjqwHtKTv7k | C50: SLAB | D50: Estribos_MurosLaterales:Estribo_MLaterales_e750_fc280:414282 | E50: ED-ML2 | F50: Estribos | G50: Margen Derecha | H50: MuroLateral | I50: MUR-MD | J50: 92.791 | K50: No iniciado
A51: 756 | B51: 2t1$kOTDX16wjqwHtKTv7H | C51: SLAB | D51: Estribos_MurosLaterales:Estribo_MLaterales_e750_fc280:414325 | E51: ED-M1 | F51: Estribos | G51: Margen Derecha | H51: MuroLateral | I51: MUR-MD | J51: 92.791 | K51: No iniciado
A52: 2078329 | B52: 31IX94I6r2efzgAGrOkFTb | C52: SLAB | D52: Estribos_MurosFrontales:Estribo_MFrontal_e1200_fc280:1525810 | E52: ED-M2 | F52: Estribos | G52: Margen Izquierda | H52: MuroFrontal | I52: MUR-MI | J52: 39.085 | K52: Ejecutado
A53: 2078371 | B53: 31IX94I6r2efzgAGrOkFTa | C53: SLAB | D53: Estribos_MurosFrontales:Estribo_MFrontal_e1200_fc280:1525811 | E53: ED-MF1 | F53: Estribos | G53: Margen Izquierda | H53: MuroFrontal | I53: MUR-MI | J53: 39.085 | K53: No iniciado
A54: 2078461 | B54: 31IX94I6r2efzgAGrOkFTZ | C54: SLAB | D54: Estribos_MurosPosterior:Estribo_MPosterior_fc280:1525812 | E54: ED-MP1 | F54: Estribos | G54: Margen Izquierda | H54: MuroPosterior | I54: MUR-MI | J54: 163.632 | K54: No iniciado
A55: 2078544 | B55: 31IX94I6r2efzgAGrOkFTY | C55: SLAB | D55: Estribos_MurosLaterales:Estribo_MLaterales_e750_fc280:1525813 | E55: ED-ML2 | F55: Estribos | G55: Margen Izquierda | H55: MuroLateral | I55: MUR-MI | J55: 92.791 | K55: No iniciado
A56: 2078627 | B56: 31IX94I6r2efzgAGrOkFTX | C56: SLAB | D56: Estribos_MurosLaterales:Estribo_MLaterales_e750_fc280:1525814 | E56: ED-M1 | F56: Estribos | G56: Margen Izquierda | H56: MuroLateral | I56: MUR-MI | J56: 92.791 | K56: No iniciado
A57: 1092440 | B57: 2MRnbnEx980x5CFH3m8sxX | C57: SLAB | D57: Estribos_Pilote:Pilote_D1500_H38000_fc280:495196 | E57: ED-P1 | F57: PruebaCargaBidirecional | G57: Margen Derecha | H57: Pilote Prueba | I57: PCB-MD | J57: 67.152 | K57: Ejecutado
A58: 1804763 | B58: 34wcEtjQf6Ye8XltIuUohc | C58: BUILDINGELEMENTPROXY | D58: Rev 01 OSTERBERG CELL:Prueba Osterberg Cell Pte Charanal:823305 | F58: PruebaCargaBidirecional | G58: Margen Derecha | H58: Celda | I58: PCB-MD | J58: 0.175 | K58: Ejecutado
A59: 2030600 | B59: 0hdRnFtwTElgX914EGMZQ9 | C59: BUILDINGELEMENTPROXY | D59: Perfil-L:L100 x 100 x12 mm:1480775 | F59: PruebaCargaBidirecional | G59: Margen Derecha | I59: PCB-MD | J59: 0.001 | K59: Ejecutado
A60: 2030667 | B60: 0hdRnFtwTElgX914EGMZQ6 | C60: BUILDINGELEMENTPROXY | D60: Perfil-L:L100 x 100 x12 mm:1480776 | F60: PruebaCargaBidirecional | G60: Margen Derecha | I60: PCB-MD | J60: 0.001 | K60: Ejecutado
...
